Workbook

Sheet Round1
A1: STEP 1 | H1: Disc All | I1: Disc Sel | J1: Basic All | K1: Basic Sel | L1: Prem All | M1: Prem Sel | O1: Cost | V1: Mult
A2: Category | B2: Premium | C2: Standard | D2: Basic | E2: Discount | F2: Total | H2: Player 1 | I2: Player 2 | J2: Player 3 | K2: Player 4 | L2: Player 5 | M2: Player 6 | O2: Player 1 | P2: Player 2 | Q2: Player 3 | R2: Player 4 | S2: Player 5 | T2: Player 6 | V2: Player 1 | W2: Player 2 | X2: Player 3 | Y2: Player 4 | Z2: Player 5 | AA2: Player 6 | AB2: Local
A3: Food | B3: 600 | C3: 1250 | D3: 1300 | E3: 1800 | F3: =SUM(B3:E3) -> 4950 | H3: 1 | I3: 1 | J3: 1 | K3: 1 | L3: 1 | M3: 1
A4: Mobile | B4: 700 | C4: 800 | D4: 700 | E4: 900 | F4: =SUM(B4:E4) -> 3100 | H4: 1 | I4: 1 | J4: 1 | L4: 1
A5: Clothes | B5: 200 | C5: 500 | D5: 700 | E5: 1200 | F5: =SUM(B5:E5) -> 2600 | H5: 1 | J5: 1 | L5: 1 | M5: 1
A6: TOTAL | B6: =SUM(B3:B5) -> 1500 | C6: =SUM(C3:C5) -> 2550 | D6: =SUM(D3:D5) -> 2700 | E6: =SUM(E3:E5) -> 3900 | F6: =SUM(F3:F5) -> 10650
A9: STEP 2 | O9: =SUM(O11:O12) -> 115000 | P9: =SUM(P11:P12) -> 115000 | Q9: =SUM(Q11:Q12) -> 115000 | R9: =SUM(R11:R12) -> 115000 | S9: =SUM(S11:S12) -> 115000 | T9: =SUM(T11:T12) -> 115000
A10: Fleet | B10: Applies To | C10: Multiplier | D10: Cost | E10: Ratio | O10: =SUM(O13:O17) -> 105000 | P10: =SUM(P13:P17) -> 90000 | Q10: =SUM(Q13:Q17) -> 123000 | R10: =SUM(R13:R17) -> 125000 | S10: =SUM(S13:S17) -> 123000 | T10: =SUM(T13:T17) -> 105000 | V10: =PRODUCT(V13:V18) -> 1.16655 | W10: =PRODUCT(W13:W18) -> 1.13526 | X10: =PRODUCT(X13:X18) -> 1.16802 | Y10: =PRODUCT(Y13:Y18) -> 1.16844 | Z10: =PRODUCT(Z13:Z18) -> 1.16802 | AA10: =PRODUCT(AA13:AA18) -> 1.16865
A11: Number of riders | B11: Slider | D11: 30000 | H11: 3 | I11: 3 | J11: 3 | K11: 3 | L11: 3 | M11: 3 | O11: =H11*$D$11 -> 90000 | P11: =I11*$D$11 -> 90000 | Q11: =J11*$D$11 -> 90000 | R11: =K11*$D$11 -> 90000 | S11: =L11*$D$11 -> 90000 | T11: =M11*$D$11 -> 90000
A12: Number of bikes | B12: Slider | D12: 25000 | H12: 1 | I12: 1 | J12: 1 | K12: 1 | L12: 1 | M12: 1 | O12: =H12*$D$12 -> 25000 | P12: =I12*$D$12 -> 25000 | Q12: =J12*$D$12 -> 25000 | R12: =K12*$D$12 -> 25000 | S12: =L12*$D$12 -> 25000 | T12: =M12*$D$12 -> 25000
A13: Route Optimization | C13: 1.1 | D13: 100000 | E13: =100000*(C13-1)/D13 -> 0.1 | H13: 1 | O13: =H13*$D13 -> 100000 | P13: =I13*$D13 -> 0 | Q13: =J13*$D13 -> 0 | R13: =K13*$D13 -> 0 | S13: =L13*$D13 -> 0 | T13: =M13*$D13 -> 0 | V13: =IF(O13>0,$C13,1) -> 1.1 | W13: =IF(P13>0,$C13,1) -> 1 | X13: =IF(Q13>0,$C13,1) -> 1 | Y13: =IF(R13>0,$C13,1) -> 1 | Z13: =IF(S13>0,$C13,1) -> 1 | AA13: =IF(T13>0,$C13,1) -> 1
A14: GPS Tracking | B14: Premium, Standard | C14: 1.06 | D14: 80000 | E14: =100000*(C14-1)/D14 -> 0.075 | I14: 1 | M14: 1 | O14: =H14*D14 -> 0 | P14: =I14*$D14 -> 80000 | Q14: =J14*$D14 -> 0 | R14: =K14*$D14 -> 0 | S14: =L14*$D14 -> 0 | T14: =M14*$D14 -> 80000 | V14: =IF(O14>0,$C14,1) -> 1 | W14: =IF(P14>0,$C14,1) -> 1.06 | X14: =IF(Q14>0,$C14,1) -> 1 | Y14: =IF(R14>0,$C14,1) -> 1 | Z14: =IF(S14>0,$C14,1) -> 1 | AA14: =IF(T14>0,$C14,1) -> 1.06
A15: Algorithm Assignment | C15: 1.08 | D15: 108000 | E15: =100000*(C15-1)/D15 -> 0.074074074 | J15: 1 | L15: 1 | O15: =H15*D15 -> 0 | P15: =I15*$D15 -> 0 | Q15: =J15*$D15 -> 108000 | R15: =K15*$D15 -> 0 | S15: =L15*$D15 -> 108000 | T15: =M15*$D15 -> 0 | V15: =IF(O15>0,$C15,1) -> 1 | W15: =IF(P15>0,$C15,1) -> 1 | X15: =IF(Q15>0,$C15,1) -> 1.08 | Y15: =IF(R15>0,$C15,1) -> 1 | Z15: =IF(S15>0,$C15,1) -> 1.08 | AA15: =IF(T15>0,$C15,1) -> 1
A16: Warehousing System | C16: 1.07 | D16: 105000 | E16: =100000*(C16-1)/D16 -> 0.066666667 | K16: 1 | O16: =H16*D16 -> 0 | P16: =I16*$D16 -> 0 | Q16: =J16*$D16 -> 0 | R16: =K16*$D16 -> 105000 | S16: =L16*$D16 -> 0 | T16: =M16*$D16 -> 0 | V16: =IF(O16>0,$C16,1) -> 1 | W16: =IF(P16>0,$C16,1) -> 1 | X16: =IF(Q16>0,$C16,1) -> 1 | Y16: =IF(R16>0,$C16,1) -> 1.07 | Z16: =IF(S16>0,$C16,1) -> 1 | AA16: =IF(T16>0,$C16,1) -> 1
A17: Electric Bikes % | B17: Competitive | C17: 0.1 | D17: 2 | H17: 0.1 | I17: 0.2 | J17: 0.3 | K17: 0.4 | L17: 0.3 | M17: 0.5 | O17: =H17*H12*$D12*$D17 -> 5000 | P17: =I17*I12*$D12*$D17 -> 10000 | Q17: =J17*J12*$D12*$D17 -> 15000 | R17: =K17*K12*$D12*$D17 -> 20000 | S17: =L17*L12*$D12*$D17 -> 15000 | T17: =M17*M12*$D12*$D17 -> 25000 | V17: =1+(O17*$C17/($D17*$D12)) -> 1.01 | W17: =1+(P17*$C17/($D17*$D12)) -> 1.02 | X17: =1+(Q17*$C17/($D17*$D12)) -> 1.03 | Y17: =1+(R17*$C17/($D17*$D12)) -> 1.04 | Z17: =1+(S17*$C17/($D17*$D12)) -> 1.03 | AA17: =1+(T17*$C17/($D17*$D12)) -> 1.05
A18: Bike-Rider Optimization | B18: Indi Efficiency | C18: 0.85 | D18: 0.95 | E18: 1.05 | V18: =IF(H11/H12<$C19,$C18,IF(H11/H12>$D19,$D18,$E18)) -> 1.05 | W18: =IF(I11/I12<$C19,$C18,IF(I11/I12>$D19,$D18,$E18)) -> 1.05 | X18: =IF(J11/J12<$C19,$C18,IF(J11/J12>$D19,$D18,$E18)) -> 1.05 | Y18: =IF(K11/K12<$C19,$C18,IF(K11/K12>$D19,$D18,$E18)) -> 1.05 | Z18: =IF(L11/L12<$C19,$C18,IF(L11/L12>$D19,$D18,$E18)) -> 1.05 | AA18: =IF(M11/M12<$C19,$C18,IF(M11/M12>$D19,$D18,$E18)) -> 1.05
C19: 2.5 | D19: 3.5
A22: STEP 3
A23: Technology | B23: Applies To | C23: Multiplier | D23: Cost | E23: Ratio | O23: =SUM(O24:O31) -> 175000 | P23: =SUM(P24:P31) -> 150000 | Q23: =SUM(Q24:Q31) -> 213000 | R23: =SUM(R24:R31) -> 173500 | S23: =SUM(S24:S31) -> 305000 | T23: =SUM(T24:T31) -> 155000 | V23: =PRODUCT(V24:V32) -> 1.06605 | W23: =PRODUCT(W24:W32) -> 1.01124 | X23: =PRODUCT(X24:X32) -> 1.1772 | Y23: =PRODUCT(Y24:Y32) -> 1.02078 | Z23: =PRODUCT(Z24:Z32) -> 1.294048 | AA23: =PRODUCT(AA24:AA32) -> 1.03824
A24: Mobile App | B24: Mandatory | C24: 1.15 | D24: 140000 | E24: =100000*(C24-1)/D24 -> 0.10714286 | H24: 1 | O24: =H24*$D24 -> 140000 | P24: =I24*$D24 -> 0 | Q24: =J24*$D24 -> 0 | R24: =K24*$D24 -> 0 | S24: =L24*$D24 -> 0 | T24: =M24*$D24 -> 0 | V24: =IF(O24>0,$C24,1) -> 1.15 | W24: =IF(P24>0,$C24,1) -> 1 | X24: =IF(Q24>0,$C24,1) -> 1 | Y24: =IF(R24>0,$C24,1) -> 1 | Z24: =IF(S24>0,$C24,1) -> 1 | AA24: =IF(T24>0,$C24,1) -> 1
A25: Voice Ordering | B25: Premium, Standard | C25: 1.06 | D25: 80000 | E25: =100000*(C25-1)/D25 -> 0.075 | I25: 1 | O25: =H25*$D25 -> 0 | P25: =I25*$D25 -> 80000 | Q25: =J25*$D25 -> 0 | R25: =K25*$D25 -> 0 | S25: =L25*$D25 -> 0 | T25: =M25*$D25 -> 0 | V25: =IF(O25>0,$C25,1) -> 1 | W25: =IF(P25>0,$C25,1) -> 1.06 | X25: =IF(Q25>0,$C25,1) -> 1 | Y25: =IF(R25>0,$C25,1) -> 1 | Z25: =IF(S25>0,$C25,1) -> 1 | AA25: =IF(T25>0,$C25,1) -> 1
A26: Dark Store System | C26: 1.08 | D26: 108000 | E26: =100000*(C26-1)/D26 -> 0.074074074 | J26: 1 | O26: =H26*$D26 -> 0 | P26: =I26*$D26 -> 0 | Q26: =J26*$D26 -> 108000 | R26: =K26*$D26 -> 0 | S26: =L26*$D26 -> 0 | T26: =M26*$D26 -> 0 | V26: =IF(O26>0,$C26,1) -> 1 | W26: =IF(P26>0,$C26,1) -> 1 | X26: =IF(Q26>0,$C26,1) -> 1.08 | Y26: =IF(R26>0,$C26,1) -> 1 | Z26: =IF(S26>0,$C26,1) -> 1 | AA26: =IF(T26>0,$C26,1) -> 1
A27: Rider App | C27: 1.07 | D27: 103500 | E27: =100000*(C27-1)/D27 -> 0.06763285 | K27: 1 | O27: =H27*$D27 -> 0 | P27: =I27*$D27 -> 0 | Q27: =J27*$D27 -> 0 | R27: =K27*$D27 -> 103500 | S27: =L27*$D27 -> 0 | T27: =M27*$D27 -> 0 | V27: =IF(O27>0,$C27,1) -> 1 | W27: =IF(P27>0,$C27,1) -> 1 | X27: =IF(Q27>0,$C27,1) -> 1 | Y27: =IF(R27>0,$C27,1) -> 1.07 | Z27: =IF(S27>0,$C27,1) -> 1 | AA27: =IF(T27>0,$C27,1) -> 1
A28: Demand Forecasting AI | C28: 1.12 | D28: 120000 | E28: =100000*(C28-1)/D28 -> 0.1 | L28: 1 | O28: =H28*$D28 -> 0 | P28: =I28*$D28 -> 0 | Q28: =J28*$D28 -> 0 | R28: =K28*$D28 -> 0 | S28: =L28*$D28 -> 120000 | T28: =M28*$D28 -> 0 | V28: =IF(O28>0,$C28,1) -> 1 | W28: =IF(P28>0,$C28,1) -> 1 | X28: =IF(Q28>0,$C28,1) -> 1 | Y28: =IF(R28>0,$C28,1) -> 1 | Z28: =IF(S28>0,$C28,1) -> 1.12 | AA28: =IF(T28>0,$C28,1) -> 1
A29: Dynamic Pricing | C29: 1.12 | D29: 120000 | E29: =100000*(C29-1)/D29 -> 0.1 | M29: 1 | O29: =H29*$D29 -> 0 | P29: =I29*$D29 -> 0 | Q29: =J29*$D29 -> 0 | R29: =K29*$D29 -> 0 | S29: =L29*$D29 -> 0 | T29: =M29*$D29 -> 120000 | V29: =IF(O29>0,$C29,1) -> 1 | W29: =IF(P29>0,$C29,1) -> 1 | X29: =IF(Q29>0,$C29,1) -> 1 | Y29: =IF(R29>0,$C29,1) -> 1 | Z29: =IF(S29>0,$C29,1) -> 1 | AA29: =IF(T29>0,$C29,1) -> 1.12
A30: Supply Chain Analytics | C30: 1.06 | D30: 80000 | E30: =100000*(C30-1)/D30 -> 0.075 | L30: 1 | O30: =H30*$D30 -> 0 | P30: =I30*$D30 -> 0 | Q30: =J30*$D30 -> 0 | R30: =K30*$D30 -> 0 | S30: =L30*$D30 -> 80000 | T30: =M30*$D30 -> 0 | V30: =IF(O30>0,$C30,1) -> 1 | W30: =IF(P30>0,$C30,1) -> 1 | X30: =IF(Q30>0,$C30,1) -> 1 | Y30: =IF(R30>0,$C30,1) -> 1 | Z30: =IF(S30>0,$C30,1) -> 1.06 | AA30: =IF(T30>0,$C30,1) -> 1
A31: Website Development | B31: Slider | C31: 0.03 | D31: 35000 | E31: =100000*(C31)/D31 -> 0.085714286 | H31: 1 | I31: 2 | J31: 3 | K31: 2 | L31: 3 | M31: 1 | O31: =H31*$D31 -> 35000 | P31: =I31*$D31 -> 70000 | Q31: =J31*$D31 -> 105000 | R31: =K31*$D31 -> 70000 | S31: =L31*$D31 -> 105000 | T31: =M31*$D31 -> 35000 | V31: =1+(O31*$C31/$D31) -> 1.03 | W31: =1+(P31*$C31/$D31) -> 1.06 | X31: =1+(Q31*$C31/$D31) -> 1.09 | Y31: =1+(R31*$C31/$D31) -> 1.06 | Z31: =1+(S31*$C31/$D31) -> 1.09 | AA31: =1+(T31*$C31/$D31) -> 1.03
A32: Total investment/average | B32: Competitive | C32: 0.9 | D32: 1 | V32: =IF(O23<AVERAGE($O$23:$T$23),$C32,$D32) -> 0.9 | W32: =IF(P23<AVERAGE($O$23:$T$23),$C32,$D32) -> 0.9 | X32: =IF(Q23<AVERAGE($O$23:$T$23),$C32,$D32) -> 1 | Y32: =IF(R23<AVERAGE($O$23:$T$23),$C32,$D32) -> 0.9 | Z32: =IF(S23<AVERAGE($O$23:$T$23),$C32,$D32) -> 1 | AA32: =IF(T23<AVERAGE($O$23:$T$23),$C32,$D32) -> 0.9
A36: STEP 4
A37: Sourcing | B37: Applies To | C37: Multiplier | D37: Cost | E37: Ratio
A38: Sustainability 5 star | B38: Premium | C38: 1.2
A39: Sustainability 4.5 star | B39: Premium | C39: 1.1
A40: Sustainability 4 star | B40: Premium | C40: 1
A41: Sustainability 3.5 star | B41: Premium | C41: 0.95
A42: Sustainability 3 star | B42: Premium | C42: 0.9
A43: Sustainability 5 star | B43: Mass | C43: 1.1
A44: Sustainability 4.5 star | B44: Mass | C44: 1.1
A45: Sustainability 4 star | B45: Mass | C45: 1.1
A46: Sustainability 3.5 star | B46: Mass | C46: 1
A47: Sustainability 3 star | B47: Mass | C47: 0.95
...

Sheet Supplier
E1: ORDER (WK) - 4 time to the supplier | F1: 500 | I1: 800 | R1: For all products/all category (sum) for round 1
E2: WEEK1 | F2: WEEK2 | G2: WEEK3 | H2: WEEK4 | I2: WEEK5 | J2: WEEK6 | K2: WEEK7 | L2: WEEK8 | M2: WEEK9 | O2: Starting Inventory | P2: New Inventory | Q2: Total invwnrtory | R2: Demand | S2: Actually Sold | T2: Ending inventory | U2: Wasted demand
B3: Supplier | E3: 0 | F3: 500 | G3: 500 | H3: 500 | I3: 500 | J3: 800 | K3: 800 | L3: 800 | M3: 800 | N3: week1 | O3: 0 | R3: =2400/4 -> 600 | S3: 0 | U3: 600
F4: 0.85 | G4: 0.88 | H4: 0.9 | I4: 0.88 | N4: week2 | P4: 425 | Q4: =O4+P4 -> 425 | R4: 600 | S4: 425 | T4: 0 | U4: 175
B5: Delivery Time | C5: 1 week | F5: =F3*F4 -> 425 | G5: =G3*G4 -> 440 | H5: =H3*H4 -> 450 | I5: =I3*I4 -> 440 | N5: week3 | P5: 440 | Q5: =O5+P5 -> 440 | R5: 600 | S5: 440 | T5: 0 | U5: 160
B6: Reliability | C6: 4 star | N6: week4 | P6: 450 | Q6: =O6+P6 -> 450 | R6: 600 | S6: 450 | T6: 0 | U6: 140
I7: 800 | J7: 800 | K7: 800 | L7: 800 | N7: week5 | P7: =440+760 -> 1200 | Q7: =O7+P7 -> 1200 | R7: =2800/4 -> 700 | S7: 700 | T7: 500 | U7: 0
A8: Reliability | B8: 5 | C8: 4.5 | D8: 4 | I8: 0.95 | J8: 0.98 | K8: 0.98 | L8: 1 | N8: week6 | O8: 500 | P8: 784 | Q8: =O8+P8 -> 1284 | R8: =2800/4 -> 700 | S8: 700 | T8: =Q8-R8 -> 584 | U8: 0
A9: Final | B9: 95-100% | C9: 90-95% | D9: 85-90% | I9: =I7*I8 -> 760 | J9: =J7*J8 -> 784 | K9: =K7*K8 -> 784 | L9: =L7*L8 -> 800 | N9: week7 | O9: =T8 -> 584 | P9: 784 | Q9: =O9+P9 -> 1368 | R9: =2800/4 -> 700 | S9: 700 | T9: =Q9-R9 -> 668 | U9: 0
A10: Random | N10: week8 | O10: =T9 -> 668 | P10: 800 | Q10: =O10+P10 -> 1468 | R10: =2800/4 -> 700 | S10: 700 | T10: =Q10-R10 -> 768 | U10: 0
B13: Delivery Time | C13: Instant | Q13: premium | R13: basic
B14: Reliability | C14: 5 star | P14: food | Q14: 100 | R14: 150
P15: electronics | Q15: 200 | R15: 150
Q17: =Q14/600 -> 0.16666667 | R17: =R14/600 -> 0.25
Q18: =Q15/600 -> 0.33333333 | R18: =R15/600 -> 0.25
P21: actual sold | Q21: =Q17*425 -> 70.833333 | R21: =R17*425 -> 106.25
Q22: =Q18*425 -> 141.66667 | R22: =R18*425 -> 106.25

Sheet Setup
A1: QUICK COMMERCE - FINANCIAL MODEL SETUP
A3: Player Name: | B3: Player 1
A4: Round: | B4: 1
A6: INITIAL CAPITAL
A8: Equity Investment | B8: 500000
A9: Loan Amount | B9: 300000
A10: Interest Rate (Annual) | B10: 0.12
A11: Total Capital | B11: =B8+B9 -> 800000
A13: GAME PARAMETERS
A15: Base Orders per Day | B15: 100
A16: Days per Month | B16: 30

Sheet Inputs
A1: GAME INPUTS - PLAYER DECISIONS
A3: Enter all game decisions here (Blue cells)
A5: CATEGORY MULTIPLIERS
C6: Month 1 | D6: Month 2 | E6: Month 3
A7: Quality Multiplier | C7: 1.15 | D7: 1.18 | E7: 1.22
A9: TOTAL INVESTMENTS
A10: Fleet Investments | C10: 165000
A11: Technology Investments | C11: 140000
A12: Marketing Spend | C12: 165000 | D12: 165000 | E12: 165000
A13: HR Costs | C13: 144500 | D13: 144500 | E13: 144500

Sheet P&L
A1: INCOME STATEMENT
A2: Player: | B2: =Setup!B3 -> Player 1
A4: Line Item | C4: Month 1 | D4: Month 2 | E4: Month 3
A6: REVENUE
A7: Premium Segment | C7: =Setup!$B$15*Setup!$B$16*12*Inputs!C$7 -> 41400 | D7: =Setup!$B$15*Setup!$B$16*12*Inputs!D$7*1.05 -> 44604 | E7: =Setup!$B$15*Setup!$B$16*12*Inputs!E$7*1.08 -> 47433.6
A8: Standard Segment | C8: =Setup!$B$15*Setup!$B$16*10*Inputs!C$7 -> 34500 | D8: =Setup!$B$15*Setup!$B$16*10*Inputs!D$7*1.05 -> 37170 | E8: =Setup!$B$15*Setup!$B$16*10*Inputs!E$7*1.08 -> 39528
A9: Basic Segment | C9: =Setup!$B$15*Setup!$B$16*8*Inputs!C$7 -> 27600 | D9: =Setup!$B$15*Setup!$B$16*8*Inputs!D$7*1.05 -> 29736 | E9: =Setup!$B$15*Setup!$B$16*8*Inputs!E$7*1.08 -> 31622.4
A10: Discount Segment | C10: =Setup!$B$15*Setup!$B$16*6*Inputs!C$7 -> 20700 | D10: =Setup!$B$15*Setup!$B$16*6*Inputs!D$7*1.05 -> 22302 | E10: =Setup!$B$15*Setup!$B$16*6*Inputs!E$7*1.08 -> 23716.8
A11: Total Revenue | C11: =SUM(C7:C10) -> 124200 | D11: =SUM(D7:D10) -> 133812 | E11: =SUM(E7:E10) -> 142300.8
A13: COST OF SALES
A14: Cost of Goods Sold (40%) | C14: =C11*0.4 -> 49680 | D14: =D11*0.4 -> 53524.8 | E14: =E11*0.4 -> 56920.32
A15: Delivery & Packaging | C15: =C11*0.15 -> 18630 | D15: =D11*0.15 -> 20071.8 | E15: =E11*0.15 -> 21345.12
A16: Total Cost of Sales | C16: =SUM(C14:C15) -> 68310 | D16: =SUM(D14:D15) -> 73596.6 | E16: =SUM(E14:E15) -> 78265.44
A17: GROSS PROFIT | C17: =C11-C16 -> 55890 | D17: =D11-D16 -> 60215.4 | E17: =E11-E16 -> 64035.36
A19: OPERATING EXPENSES
A20: Fleet Costs | C20: =Inputs!C9/12 -> 0 | D20: =Inputs!C9/12 -> 0 | E20: =Inputs!C9/12 -> 0
A21: Technology Costs | C21: =Inputs!C10/12 -> 13750 | D21: =Inputs!C10/12 -> 13750 | E21: =Inputs!C10/12 -> 13750
A22: Marketing Expenses | C22: =Inputs!C11 -> 140000 | D22: =Inputs!D11 -> 0 | E22: =Inputs!E11 -> 0
A23: HR & Operations | C23: =Inputs!C12 -> 165000 | D23: =Inputs!D12 -> 165000 | E23: =Inputs!E12 -> 165000
A24: Rent & Utilities | C24: 25000 | D24: 25000 | E24: 25000
A25: Total Operating Expenses | C25: =SUM(C20:C24) -> 343750 | D25: =SUM(D20:D24) -> 203750 | E25: =SUM(E20:E24) -> 203750
A26: EBITDA | C26: =C17-C25 -> -287860 | D26: =D17-D25 -> -143534.6 | E26: =E17-E25 -> -139714.64
A27: Depreciation & Amortization | C27: 5000 | D27: 5000 | E27: 5000
A28: EBIT | C28: =C26-C27 -> -292860 | D28: =D26-D27 -> -148534.6 | E28: =E26-E27 -> -144714.64
A29: Interest Expense | C29: =Setup!$B$9*Setup!$B$10/12 -> 3000 | D29: =Setup!$B$9*Setup!$B$10/12 -> 3000 | E29: =Setup!$B$9*Setup!$B$10/12 -> 3000
A30: NET INCOME | C30: =C28-C29 -> -295860 | D30: =D28-D29 -> -151534.6 | E30: =E28-E29 -> -147714.64

Sheet Balance Sheet
A1: BALANCE SHEET
A2: Player: | B2: =Setup!B3 -> Player 1
A4: Account | B4: Beginning | C4: Month 1 | D4: Month 2 | E4: Month 3
A6: ASSETS
A7: Current Assets
A8: Cash | B8: =Setup!B11 -> 800000 | C8: =B8+CashFlow!C30 -> 800000 | D8: =C8+CashFlow!D30 -> 800000 | E8: =D8+CashFlow!E30 -> 800000
A9: Accounts Receivable | B9: 0 | C9: 25000 | D9: 28000 | E9: 32000
A10: Inventory | B10: 50000 | C10: 55000 | D10: 58000 | E10: 62000
A11: Total Current Assets | B11: =SUM(B8:B10) -> 850000 | C11: =SUM(C8:C10) -> 880000 | D11: =SUM(D8:D10) -> 886000 | E11: =SUM(E8:E10) -> 894000
A13: Fixed Assets
A14: Property & Equipment | B14: 100000 | C14: 100000 | D14: 100000 | E14: 100000
A15: Less: Accum. Depreciation | B15: 0 | C15: -5000 | D15: -10000 | E15: -15000
A16: Intangible Assets | B16: 50000 | C16: 50000 | D16: 50000 | E16: 50000
A17: Total Fixed Assets | B17: =SUM(B13:B15) -> 100000 | C17: =SUM(C13:C15) -> 95000 | D17: =SUM(D13:D15) -> 90000 | E17: =SUM(E13:E15) -> 85000
A18: TOTAL ASSETS | B18: =B11+B17 -> 950000 | C18: =C11+C17 -> 975000 | D18: =D11+D17 -> 976000 | E18: =E11+E17 -> 979000
A20: LIABILITIES & EQUITY
A21: Current Liabilities
A22: Accounts Payable | B22: 30000 | C22: 35000 | D22: 38000 | E22: 42000
A23: Accrued Expenses | B23: 15000 | C23: 18000 | D23: 20000 | E23: 22000
A24: Total Current Liabilities | B24: =SUM(B21:B22) -> 30000 | C24: =SUM(C21:C22) -> 35000 | D24: =SUM(D21:D22) -> 38000 | E24: =SUM(E21:E22) -> 42000
A26: Long-term Liabilities
A27: Long-term Debt | B27: =Setup!B9 -> 300000 | C27: =Setup!B9 -> 300000 | D27: =Setup!B9 -> 300000 | E27: =Setup!B9 -> 300000
A28: Total Liabilities | B28: =B24+B27 -> 330000 | C28: =C24+C27 -> 335000 | D28: =D24+D27 -> 338000 | E28: =E24+E27 -> 342000
A30: Equity
A31: Share Capital | B31: =Setup!B8 -> 500000 | C31: =Setup!B8 -> 500000 | D31: =Setup!B8 -> 500000 | E31: =Setup!B8 -> 500000
A32: Retained Earnings | B32: 0 | C32: ='P&L'!C30 -> -295860 | D32: =C32+'P&L'!D30 -> -447394.6 | E32: =D32+'P&L'!E30 -> -595109.24
A33: Total Equity | B33: =B31+B32 -> 500000 | C33: =C31+C32 -> 204140 | D33: =D31+D32 -> 52605.4 | E33: =E31+E32 -> -95109.24
A34: TOTAL LIABILITIES & EQUITY | B34: =B28+B33 -> 830000 | C34: =C28+C33 -> 539140 | D34: =D28+D33 -> 390605.4 | E34: =E28+E33 -> 246890.76
A36: BALANCE CHECK (Should be 0) | B36: =B18-B34 -> 120000 | C36: =C18-C34 -> 435860 | D36: =D18-D34 -> 585394.6 | E36: =E18-E34 -> 732109.24

Sheet CashFlow
A1: CASH FLOW STATEMENT
A2: Player: | B2: =Setup!B3 -> Player 1
A4: Activity | C4: Month 1 | D4: Month 2 | E4: Month 3
A6: OPERATING ACTIVITIES
A7: Net Income | C7: ='P&L'!C30 -> -295860 | D7: ='P&L'!D30 -> -151534.6 | E7: ='P&L'!E30 -> -147714.64
A8: Add: Depreciation | C8: 5000 | D8: 5000 | E8: 5000
A9: (Increase) in AR | C9: -25000 | D9: -3000 | E9: -4000
A10: (Increase) in Inventory | C10: -5000 | D10: -3000 | E10: -4000
A11: Increase in AP | C11: 5000 | D11: 3000 | E11: 4000
A12: Increase in Accrued Exp | C12: 3000 | D12: 2000 | E12: 2000
A13: Net Cash from Operations | C13: =SUM(C7:C12) -> -312860 | D13: =SUM(D7:D12) -> -147534.6 | E13: =SUM(E7:E12) -> -144714.64
A15: INVESTING ACTIVITIES
A16: Equipment Purchases | C16: 0 | D16: 0 | E16: 0
A17: Technology Investments | C17: -10000 | D17: -5000 | E17: -8000
A18: Net Cash from Investing | C18: =SUM(C16:C17) -> -10000 | D18: =SUM(D16:D17) -> -5000 | E18: =SUM(E16:E17) -> -8000
A20: FINANCING ACTIVITIES
A21: Equity Proceeds | C21: 0 | D21: 0 | E21: 0
A22: Loan Proceeds/(Repayment) | C22: 0 | D22: 0 | E22: 0
A23: Net Cash from Financing | C23: =SUM(C21:C22) -> 0 | D23: =SUM(D21:D22) -> 0 | E23: =SUM(E21:E22) -> 0
A25: NET CHANGE IN CASH | C25: =C13+C18+C23 -> -322860 | D25: =D13+D18+D23 -> -152534.6 | E25: =E13+E18+E23 -> -152714.64
A27: Cash - Beginning | C27: =Setup!B11 -> 800000 | D27: =C28 -> 477140 | E27: =D28 -> 324605.4
A28: Cash - Ending | C28: =C27+C25 -> 477140 | D28: =D27+D25 -> 324605.4 | E28: =E27+E25 -> 171890.76
